Workbook

Sheet Dashboard
A1: NGFW Maturity Engagement – Dashboard
A2: ="Client: "&Inputs!B3&" | As of "&TEXT(Inputs!B7,"mmm d, yyyy")
A4: Project Start | B4: =Inputs!B5
A5: Project End | B5: =Inputs!B6
A6: Total Working Days | B6: =NETWORKDAYS(Inputs!B5,Inputs!B6,Inputs!$A$16:$A$21)
A7: Working Days Elapsed | B7: =MAX(0,MIN(B6,NETWORKDAYS(Inputs!B5,Inputs!B7,Inputs!$A$16:$A$21)))
A8: Schedule Elapsed % | B8: =IFERROR(B7/B6,0)
A9: Overall % Complete | B9: ='Project Plan'!G51
A10: Tasks Late / Late Start | B10: =COUNTIF('Project Plan'!H5:H49,"Late")+COUNTIF('Project Plan'!H5:H49,"Late Start")
A11: Open High Risks | B11: =COUNTIFS('Risks & Issues'!G4:G40,"High",'Risks & Issues'!J4:J40,"Open")
A13: Phase Summary
A14: Phase | B14: Start | C14: Finish | D14: Work Days | E14: % Complete | F14: Status
A15: ='Project Plan'!B5 | B15: ='Project Plan'!D5 | C15: ='Project Plan'!E5 | D15: ='Project Plan'!F5 | E15: ='Project Plan'!G5 | F15: ='Project Plan'!H5
A16: ='Project Plan'!B10 | B16: ='Project Plan'!D10 | C16: ='Project Plan'!E10 | D16: ='Project Plan'!F10 | E16: ='Project Plan'!G10 | F16: ='Project Plan'!H10
A17: ='Project Plan'!B17 | B17: ='Project Plan'!D17 | C17: ='Project Plan'!E17 | D17: ='Project Plan'!F17 | E17: ='Project Plan'!G17 | F17: ='Project Plan'!H17
A18: ='Project Plan'!B23 | B18: ='Project Plan'!D23 | C18: ='Project Plan'!E23 | D18: ='Project Plan'!F23 | E18: ='Project Plan'!G23 | F18: ='Project Plan'!H23
A19: ='Project Plan'!B27 | B19: ='Project Plan'!D27 | C19: ='Project Plan'!E27 | D19: ='Project Plan'!F27 | E19: ='Project Plan'!G27 | F19: ='Project Plan'!H27
A20: ='Project Plan'!B31 | B20: ='Project Plan'!D31 | C20: ='Project Plan'!E31 | D20: ='Project Plan'!F31 | E20: ='Project Plan'!G31 | F20: ='Project Plan'!H31
A21: ='Project Plan'!B35 | B21: ='Project Plan'!D35 | C21: ='Project Plan'!E35 | D21: ='Project Plan'!F35 | E21: ='Project Plan'!G35 | F21: ='Project Plan'!H35
A22: ='Project Plan'!B44 | B22: ='Project Plan'!D44 | C22: ='Project Plan'!E44 | D22: ='Project Plan'!F44 | E22: ='Project Plan'!G44 | F22: ='Project Plan'!H44
A24: Methodology: Weeks 1–4 Discovery → Gaps → Future State → Roadmap & Readout | Weeks 5–16 Remediation → Validation & Closeout

Sheet Project Plan
A1: NGFW Maturity Engagement – Project Plan
A2: ="Client: "&Inputs!B3&" | "&TEXT(Inputs!B5,"mmm d, yyyy")&" – "&TEXT(Inputs!B6,"mmm d, yyyy")&" | As of: "&TEXT(Inputs!B7,"mmm d, yyyy")
L3: Week of (Mon)
A4: WBS | B4: Phase / Task | C4: Owner | D4: Start | E4: Finish | F4: Work Days | G4: % Complete | H4: Status | I4: Predecessor | J4: Deliverable / Output | K4: Notes | L4: 46279 | M4: 46286 | N4: 46293 | O4: 46300 | P4: 46307 | Q4: 46314 | R4: 46321 | S4: 46328 | T4: 46335 | U4: 46342 | V4: 46349 | W4: 46356 | X4: 46363 | Y4: 46370 | Z4: 46377 | AA4: 46384
A5: 0 | B5: Project Mobilization & Governance | D5: =MIN(D6:D9) | E5: =MAX(E6:E9) | F5: =NETWORKDAYS(D5,E5,Inputs!$A$16:$A$21) | G5: =IFERROR(SUMPRODUCT(F6:F9,G6:G9)/SUM(F6:F9),0) | H5: =IF(G5>=1,"Complete",IF(G5>0,"In Progress","Not Started"))
A6: 0.1 | B6: Contract / SOW confirmation & resourcing | C6: Consultant | D6: 46279 | E6: 46280 | F6: =NETWORKDAYS(D6,E6,Inputs!$A$16:$A$21) | G6: 1 | H6: =IF(G6>=1,"Complete",IF(E6<Inputs!$B$7,"Late",IF(G6>0,"In Progress",IF(D6<=Inputs!$B$7,"Late Start","Not Started")))) | J6: SOW baseline
A7: 0.2 | B7: Kickoff meeting & stakeholder alignment | C7: Joint | D7: 46281 | E7: 46281 | F7: =NETWORKDAYS(D7,E7,Inputs!$A$16:$A$21) | G7: 1 | H7: =IF(G7>=1,"Complete",IF(E7<Inputs!$B$7,"Late",IF(G7>0,"In Progress",IF(D7<=Inputs!$B$7,"Late Start","Not Started")))) | I7: 0.1 | J7: Kickoff deck, stakeholder map
A8: 0.3 | B8: Data request & access provisioning (configs, diagrams, tooling) | C8: Client | D8: 46281 | E8: 46283 | F8: =NETWORKDAYS(D8,E8,Inputs!$A$16:$A$21) | G8: 1 | H8: =IF(G8>=1,"Complete",IF(E8<Inputs!$B$7,"Late",IF(G8>0,"In Progress",IF(D8<=Inputs!$B$7,"Late Start","Not Started")))) | I8: 0.2 | J8: Data request tracker
A9: 0.4 | B9: Weekly status reporting & steering committee (recurring) | C9: Consultant | D9: 46286 | E9: 46387 | F9: =NETWORKDAYS(D9,E9,Inputs!$A$16:$A$21) | G9: 0.15 | H9: =IF(G9>=1,"Complete",IF(E9<Inputs!$B$7,"Late",IF(G9>0,"In Progress",IF(D9<=Inputs!$B$7,"Late Start","Not Started")))) | I9: 0.2 | J9: Weekly status reports
A10: 1 | B10: Phase 1 – Discovery (Current State) | D10: =MIN(D11:D16) | E10: =MAX(E11:E16) | F10: =NETWORKDAYS(D10,E10,Inputs!$A$16:$A$21) | G10: =IFERROR(SUMPRODUCT(F11:F16,G11:G16)/SUM(F11:F16),0) | H10: =IF(G10>=1,"Complete",IF(G10>0,"In Progress","Not Started"))
A11: 1.1 | B11: Stakeholder interviews (NetSec, NetEng, SecOps, GRC, App owners) | C11: Consultant | D11: 46281 | E11: 46287 | F11: =NETWORKDAYS(D11,E11,Inputs!$A$16:$A$21) | G11: 1 | H11: =IF(G11>=1,"Complete",IF(E11<Inputs!$B$7,"Late",IF(G11>0,"In Progress",IF(D11<=Inputs!$B$7,"Late Start","Not Started")))) | I11: 0.2 | J11: Interview notes
A12: 1.2 | B12: Firewall inventory: platforms, versions, HA, licensing, EoL/EoS | C12: Joint | D12: 46281 | E12: 46287 | F12: =NETWORKDAYS(D12,E12,Inputs!$A$16:$A$21) | G12: 1 | H12: =IF(G12>=1,"Complete",IF(E12<Inputs!$B$7,"Late",IF(G12>0,"In Progress",IF(D12<=Inputs!$B$7,"Late Start","Not Started")))) | I12: 0.3 | J12: Asset inventory
A13: 1.3 | B13: Configuration & rulebase collection / export | C13: Client | D13: 46281 | E13: 46286 | F13: =NETWORKDAYS(D13,E13,Inputs!$A$16:$A$21) | G13: 1 | H13: =IF(G13>=1,"Complete",IF(E13<Inputs!$B$7,"Late",IF(G13>0,"In Progress",IF(D13<=Inputs!$B$7,"Late Start","Not Started")))) | I13: 0.3 | J13: Config exports
A14: 1.4 | B14: Topology & segmentation mapping (DC, campus, cloud, remote/SASE) | C14: Consultant | D14: 46286 | E14: 46289 | F14: =NETWORKDAYS(D14,E14,Inputs!$A$16:$A$21) | G14: 1 | H14: =IF(G14>=1,"Complete",IF(E14<Inputs!$B$7,"Late",IF(G14>0,"In Progress",IF(D14<=Inputs!$B$7,"Late Start","Not Started")))) | I14: 1.2 | J14: Draft topology
A15: 1.5 | B15: Operational process & tooling review (change mgmt, SIEM, NAC, IdP) | C15: Consultant | D15: 46287 | E15: 46290 | F15: =NETWORKDAYS(D15,E15,Inputs!$A$16:$A$21) | G15: 1 | H15: =IF(G15>=1,"Complete",IF(E15<Inputs!$B$7,"Late",IF(G15>0,"In Progress",IF(D15<=Inputs!$B$7,"Late Start","Not Started")))) | I15: 1.1
A16: 1.6 | B16: DELIVERABLE: Firewall Estate Architecture (current state) | C16: Consultant | D16: 46289 | E16: 46294 | F16: =NETWORKDAYS(D16,E16,Inputs!$A$16:$A$21) | G16: 0.7 | H16: =IF(G16>=1,"Complete",IF(E16<Inputs!$B$7,"Late",IF(G16>0,"In Progress",IF(D16<=Inputs!$B$7,"Late Start","Not Started")))) | I16: 1.4 | J16: D1 – Firewall Estate Architecture
A17: 2 | B17: Phase 2 – Identify Pain Points, Issues & Gaps | D17: =MIN(D18:D22) | E17: =MAX(E18:E22) | F17: =NETWORKDAYS(D17,E17,Inputs!$A$16:$A$21) | G17: =IFERROR(SUMPRODUCT(F18:F22,G18:G22)/SUM(F18:F22),0) | H17: =IF(G17>=1,"Complete",IF(G17>0,"In Progress","Not Started"))
A18: 2.1 | B18: Rulebase hygiene analysis (shadowed, unused, any/any, overly permissive) | C18: Consultant | D18: 46288 | E18: 46294 | F18: =NETWORKDAYS(D18,E18,Inputs!$A$16:$A$21) | G18: 0.5 | H18: =IF(G18>=1,"Complete",IF(E18<Inputs!$B$7,"Late",IF(G18>0,"In Progress",IF(D18<=Inputs!$B$7,"Late Start","Not Started")))) | I18: 1.3
A19: 2.2 | B19: NGFW feature utilization review (App-ID, User-ID, TLS decryption, IPS, URL, sandboxing) | C19: Consultant | D19: 46288 | E19: 46294 | F19: =NETWORKDAYS(D19,E19,Inputs!$A$16:$A$21) | G19: 0.5 | H19: =IF(G19>=1,"Complete",IF(E19<Inputs!$B$7,"Late",IF(G19>0,"In Progress",IF(D19<=Inputs!$B$7,"Late Start","Not Started")))) | I19: 1.3
A20: 2.3 | B20: Maturity scoring (NIST CSF / CIS / vendor best practice) & lifecycle risk review | C20: Consultant | D20: 46293 | E20: 46296 | F20: =NETWORKDAYS(D20,E20,Inputs!$A$16:$A$21) | G20: 0.1 | H20: =IF(G20>=1,"Complete",IF(E20<Inputs!$B$7,"Late",IF(G20>0,"In Progress",IF(D20<=Inputs!$B$7,"Late Start","Not Started")))) | I20: 1.6 | J20: Maturity scorecard
A21: 2.4 | B21: Gap & pain-point validation workshop | C21: Joint | D21: 46296 | E21: 46296 | F21: =NETWORKDAYS(D21,E21,Inputs!$A$16:$A$21) | G21: 0 | H21: =IF(G21>=1,"Complete",IF(E21<Inputs!$B$7,"Late",IF(G21>0,"In Progress",IF(D21<=Inputs!$B$7,"Late Start","Not Started")))) | I21: 2.3 | J21: Workshop output
A22: 2.5 | B22: DELIVERABLE: Problem Areas & Gaps Assessment document | C22: Consultant | D22: 46295 | E22: 46297 | F22: =NETWORKDAYS(D22,E22,Inputs!$A$16:$A$21) | G22: 0 | H22: =IF(G22>=1,"Complete",IF(E22<Inputs!$B$7,"Late",IF(G22>0,"In Progress",IF(D22<=Inputs!$B$7,"Late Start","Not Started")))) | I22: 2.4 | J22: D2 – Gaps Assessment
A23: 3 | B23: Phase 3 – Define Future State Vision | D23: =MIN(D24:D26) | E23: =MAX(E24:E26) | F23: =NETWORKDAYS(D23,E23,Inputs!$A$16:$A$21) | G23: =IFERROR(SUMPRODUCT(F24:F26,G24:G26)/SUM(F24:F26),0) | H23: =IF(G23>=1,"Complete",IF(G23>0,"In Progress","Not Started"))
A24: 3.1 | B24: Requirements, guiding principles & target architecture options | C24: Consultant | D24: 46295 | E24: 46297 | F24: =NETWORKDAYS(D24,E24,Inputs!$A$16:$A$21) | G24: 0 | H24: =IF(G24>=1,"Complete",IF(E24<Inputs!$B$7,"Late",IF(G24>0,"In Progress",IF(D24<=Inputs!$B$7,"Late Start","Not Started")))) | I24: 2.4 | J24: Options analysis
A25: 3.2 | B25: Future-state vision workshop & option selection | C25: Joint | D25: 46300 | E25: 46300 | F25: =NETWORKDAYS(D25,E25,Inputs!$A$16:$A$21) | G25: 0 | H25: =IF(G25>=1,"Complete",IF(E25<Inputs!$B$7,"Late",IF(G25>0,"In Progress",IF(D25<=Inputs!$B$7,"Late Start","Not Started")))) | I25: 3.1 | J25: Decision log
A26: 3.3 | B26: Future-state architecture, target operating model & maturity targets | C26: Consultant | D26: 46300 | E26: 46301 | F26: =NETWORKDAYS(D26,E26,Inputs!$A$16:$A$21) | G26: 0 | H26: =IF(G26>=1,"Complete",IF(E26<Inputs!$B$7,"Late",IF(G26>0,"In Progress",IF(D26<=Inputs!$B$7,"Late Start","Not Started")))) | I26: 3.2 | J26: Future-state architecture
A27: 4 | B27: Phase 4 – Remediation Plan & Modernization Roadmap | D27: =MIN(D28:D30) | E27: =MAX(E28:E30) | F27: =NETWORKDAYS(D27,E27,Inputs!$A$16:$A$21) | G27: =IFERROR(SUMPRODUCT(F28:F30,G28:G30)/SUM(F28:F30),0) | H27: =IF(G27>=1,"Complete",IF(G27>0,"In Progress","Not Started"))
A28: 4.1 | B28: Gap-to-initiative mapping, prioritization & sequencing | C28: Joint | D28: 46300 | E28: 46302 | F28: =NETWORKDAYS(D28,E28,Inputs!$A$16:$A$21) | G28: 0 | H28: =IF(G28>=1,"Complete",IF(E28<Inputs!$B$7,"Late",IF(G28>0,"In Progress",IF(D28<=Inputs!$B$7,"Late Start","Not Started")))) | I28: 3.2 | J28: Prioritization matrix
A29: 4.2 | B29: DELIVERABLE: Modernization Roadmap (incl. remediation plan) | C29: Consultant | D29: 46302 | E29: 46303 | F29: =NETWORKDAYS(D29,E29,Inputs!$A$16:$A$21) | G29: 0 | H29: =IF(G29>=1,"Complete",IF(E29<Inputs!$B$7,"Late",IF(G29>0,"In Progress",IF(D29<=Inputs!$B$7,"Late Start","Not Started")))) | I29: 4.1 | J29: D3 – Modernization Roadmap
A30: 4.3 | B30: Milestone: Executive readout – D1, D2, D3 presented & accepted | C30: Joint | D30: 46304 | E30: 46304 | F30: =NETWORKDAYS(D30,E30,Inputs!$A$16:$A$21) | G30: 0 | H30: =IF(G30>=1,"Complete",IF(E30<Inputs!$B$7,"Late",IF(G30>0,"In Progress",IF(D30<=Inputs!$B$7,"Late Start","Not Started")))) | I30: 4.2 | J30: Executive readout deck
A31: 5 | B31: Phase 5 – Remediation Mobilization | D31: =MIN(D32:D34) | E31: =MAX(E32:E34) | F31: =NETWORKDAYS(D31,E31,Inputs!$A$16:$A$21) | G31: =IFERROR(SUMPRODUCT(F32:F34,G32:G34)/SUM(F32:F34),0) | H31: =IF(G31>=1,"Complete",IF(G31>0,"In Progress","Not Started"))
A32: 5.1 | B32: Detailed remediation work plan, change windows & CAB scheduling | C32: Joint | D32: 46308 | E32: 46310 | F32: =NETWORKDAYS(D32,E32,Inputs!$A$16:$A$21) | G32: 0 | H32: =IF(G32>=1,"Complete",IF(E32<Inputs!$B$7,"Late",IF(G32>0,"In Progress",IF(D32<=Inputs!$B$7,"Late Start","Not Started")))) | I32: 4.3 | J32: D4 – Remediation Execution Plan
A33: 5.2 | B33: Config backups, rollback procedures & test / validation plans | C33: Consultant | D33: 46308 | E33: 46311 | F33: =NETWORKDAYS(D33,E33,Inputs!$A$16:$A$21) | G33: 0 | H33: =IF(G33>=1,"Complete",IF(E33<Inputs!$B$7,"Late",IF(G33>0,"In Progress",IF(D33<=Inputs!$B$7,"Late Start","Not Started")))) | I33: 4.3 | J33: Rollback & test plans
A34: 5.3 | B34: Milestone: Remediation go / no-go | C34: Joint | D34: 46311 | E34: 46311 | F34: =NETWORKDAYS(D34,E34,Inputs!$A$16:$A$21) | G34: 0 | H34: =IF(G34>=1,"Complete",IF(E34<Inputs!$B$7,"Late",IF(G34>0,"In Progress",IF(D34<=Inputs!$B$7,"Late Start","Not Started")))) | I34: 5.1
A35: 6 | B35: Phase 6 – Remediation Execution | D35: =MIN(D36:D43) | E35: =MAX(E36:E43) | F35: =NETWORKDAYS(D35,E35,Inputs!$A$16:$A$21) | G35: =IFERROR(SUMPRODUCT(F36:F43,G36:G43)/SUM(F36:F43),0) | H35: =IF(G35>=1,"Complete",IF(G35>0,"In Progress","Not Started"))
A36: 6.1 | B36: Quick wins: rulebase cleanup (unused, shadowed, any/any, redundant objects) | C36: Joint | D36: 46314 | E36: 46332 | F36: =NETWORKDAYS(D36,E36,Inputs!$A$16:$A$21) | G36: 0 | H36: =IF(G36>=1,"Complete",IF(E36<Inputs!$B$7,"Late",IF(G36>0,"In Progress",IF(D36<=Inputs!$B$7,"Late Start","Not Started")))) | I36: 5.3 | J36: Cleanup change records
A37: 6.2 | B37: Software / firmware upgrades & EoL/EoS hardware remediation | C37: Joint | D37: 46321 | E37: 46346 | F37: =NETWORKDAYS(D37,E37,Inputs!$A$16:$A$21) | G37: 0 | H37: =IF(G37>=1,"Complete",IF(E37<Inputs!$B$7,"Late",IF(G37>0,"In Progress",IF(D37<=Inputs!$B$7,"Late Start","Not Started")))) | I37: 5.3 | J37: Upgrade change records
A38: 6.3 | B38: Logging, SIEM integration & monitoring / alerting tuning | C38: Consultant | D38: 46321 | E38: 46339 | F38: =NETWORKDAYS(D38,E38,Inputs!$A$16:$A$21) | G38: 0 | H38: =IF(G38>=1,"Complete",IF(E38<Inputs!$B$7,"Late",IF(G38>0,"In Progress",IF(D38<=Inputs!$B$7,"Late Start","Not Started")))) | I38: 5.3
A39: 6.4 | B39: Enable NGFW security profiles (App-ID migration, User-ID, IPS, URL, sandboxing) | C39: Joint | D39: 46328 | E39: 46360 | F39: =NETWORKDAYS(D39,E39,Inputs!$A$16:$A$21) | G39: 0 | H39: =IF(G39>=1,"Complete",IF(E39<Inputs!$B$7,"Late",IF(G39>0,"In Progress",IF(D39<=Inputs!$B$7,"Late Start","Not Started")))) | I39: 6.1
A40: 6.5 | B40: Segmentation & zone redesign (zero trust alignment) | C40: Joint | D40: 46335 | E40: 46367 | F40: =NETWORKDAYS(D40,E40,Inputs!$A$16:$A$21) | G40: 0 | H40: =IF(G40>=1,"Complete",IF(E40<Inputs!$B$7,"Late",IF(G40>0,"In Progress",IF(D40<=Inputs!$B$7,"Late Start","Not Started")))) | I40: 6.1
...

Sheet Deliverables
A1: Engagement Deliverables
A3: ID | B3: Deliverable | C3: Description / Key Contents | D3: Format | E3: Plan WBS | F3: Draft Due | G3: Final Due | H3: Client Approver | I3: Status
A4: D1 | B4: Firewall Estate Architecture | C4: Current-state inventory (platforms, versions, HA, licensing, EoL); logical & physical topology; zones/segmentation; traffic flows; management plane & integrations (SIEM, IdP, NAC, orchestration). | D4: Visio/PDF + Excel inventory | E4: 1.6 | F4: =WORKDAY('Project Plan'!E16,-1,Inputs!$A$16:$A$21) | G4: ='Project Plan'!E16 | H4: Network Security Lead | I4: ='Project Plan'!H16
A5: D2 | B5: Problem Areas & Gaps Assessment | C5: Pain points from interviews; rulebase hygiene findings; NGFW feature-utilization gaps; lifecycle/capacity risks; process & tooling gaps; maturity scorecard (current vs. target) with risk ratings. | D5: Word/PDF report | E5: 2.5 | F5: =WORKDAY('Project Plan'!E22,-1,Inputs!$A$16:$A$21) | G5: ='Project Plan'!E22 | H5: CISO | I5: ='Project Plan'!H22
A6: D3 | B6: Modernization Roadmap | C6: Future-state vision & target architecture; remediation initiatives mapped to gaps; prioritization; phased sequencing (0–3 / 3–12 / 12–24 mo); budget ranges, resourcing, KPIs. | D6: PowerPoint + Excel roadmap | E6: 4.2 | F6: =WORKDAY('Project Plan'!E29,-1,Inputs!$A$16:$A$21) | G6: ='Project Plan'!E29 | H6: CISO | I6: ='Project Plan'!H29
A7: S1 | B7: Executive Readout | C7: Presentation of D1, D2 and D3 to steering committee; approval to proceed with remediation. | D7: PowerPoint | E7: 4.3 | F7: =WORKDAY('Project Plan'!E30,-1,Inputs!$A$16:$A$21) | G7: ='Project Plan'!E30 | H7: Executive Sponsor | I7: ='Project Plan'!H30
A8: D4 | B8: Remediation Execution Plan | C8: Detailed work packages, change windows, CAB schedule, rollback and test plans for in-engagement remediation. | D8: Excel + Word | E8: 5.1 | F8: =WORKDAY('Project Plan'!E32,-1,Inputs!$A$16:$A$21) | G8: ='Project Plan'!E32 | H8: Network Security Lead | I8: ='Project Plan'!H32
A9: D5 | B9: Post-Remediation Report | C9: Validation results, maturity re-score vs. baseline, as-built architecture, remaining roadmap items. | D9: Word/PDF + Visio | E9: 7.2 | F9: =WORKDAY('Project Plan'!E46,-1,Inputs!$A$16:$A$21) | G9: ='Project Plan'!E46 | H9: CISO | I9: ='Project Plan'!H46
A11: Draft Due = 1 working day before final (assumption: client review window). Green = linked to Project Plan.

Sheet Milestones
A1: Key Milestones
A3: WBS | B3: Milestone | C3: Date | D3: Days from Today | E3: Status
A4: 0.2 | B4: ='Project Plan'!B7 | C4: ='Project Plan'!E7 | D4: =C4-Inputs!$B$7 | E4: ='Project Plan'!H7
A5: 1.6 | B5: ='Project Plan'!B16 | C5: ='Project Plan'!E16 | D5: =C5-Inputs!$B$7 | E5: ='Project Plan'!H16
A6: 2.5 | B6: ='Project Plan'!B22 | C6: ='Project Plan'!E22 | D6: =C6-Inputs!$B$7 | E6: ='Project Plan'!H22
A7: 4.2 | B7: ='Project Plan'!B29 | C7: ='Project Plan'!E29 | D7: =C7-Inputs!$B$7 | E7: ='Project Plan'!H29
A8: 4.3 | B8: ='Project Plan'!B30 | C8: ='Project Plan'!E30 | D8: =C8-Inputs!$B$7 | E8: ='Project Plan'!H30
A9: 5.3 | B9: ='Project Plan'!B34 | C9: ='Project Plan'!E34 | D9: =C9-Inputs!$B$7 | E9: ='Project Plan'!H34
A10: 6.8 | B10: ='Project Plan'!B43 | C10: ='Project Plan'!E43 | D10: =C10-Inputs!$B$7 | E10: ='Project Plan'!H43
A11: 7.2 | B11: ='Project Plan'!B46 | C11: ='Project Plan'!E46 | D11: =C11-Inputs!$B$7 | E11: ='Project Plan'!H46
A12: 7.5 | B12: ='Project Plan'!B49 | C12: ='Project Plan'!E49 | D12: =C12-Inputs!$B$7 | E12: ='Project Plan'!H49

Sheet RACI
A1: RACI Matrix
A3: Activity | B3: Engagement Lead | C3: NGFW Architect | D3: Security Analyst | E3: Client Sponsor / CISO | F3: Client NetSec Team | G3: Client SecOps / GRC
A4: Mobilization & governance | B4: A | C4: C | D4: I | E4: R | F4: C | G4: I
A5: Discovery & data collection | B5: A | C5: R | D5: R | E5: I | F5: C | G5: C
A6: D1 Firewall Estate Architecture | B6: A | C6: R | D6: C | E6: I | F6: C | G6: I
A7: D2 Problem Areas & Gaps Assessment | B7: A | C7: R | D7: R | E7: C | F7: C | G7: C
A8: Future-state vision | B8: R | C8: R | D8: C | E8: A | F8: C | G8: C
A9: D3 Modernization Roadmap | B9: A | C9: R | D9: C | E9: C | F9: C | G9: I
A10: Executive readout (D1–D3) | B10: R | C10: C | D10: I | E10: A | F10: I | G10: I
A11: D4 Remediation Execution Plan | B11: A | C11: R | D11: C | E11: C | F11: R | G11: C
A12: Remediation execution & change implementation | B12: A | C12: R | D12: R | E12: I | F12: R | G12: C
A13: Validation & D5 Post-Remediation Report | B13: A | C13: R | D13: R | E13: C | F13: C | G13: C
A15: R = Responsible · A = Accountable · C = Consulted · I = Informed

Sheet Risks & Issues
A1: RAID – Risks & Issues Log
A3: ID | B3: Type | C3: Description | D3: Impact (1-5) | E3: Likelihood (1-5) | F3: Score | G3: Rating | H3: Mitigation | I3: Owner | J3: Status
A4: R1 | B4: Risk | C4: Delayed access to firewall configs / management consoles | D4: 4 | E4: 3 | F4: =D4*E4 | G4: =IF(F4>=15,"High",IF(F4>=8,"Medium","Low")) | H4: Escalate via sponsor at kickoff; track in data request log | I4: Client | J4: Open
A5: R2 | B5: Risk | C5: Stakeholder availability for interviews/workshops | D5: 3 | E5: 3 | F5: =D5*E5 | G5: =IF(F5>=15,"High",IF(F5>=8,"Medium","Low")) | H5: Schedule all sessions in first 2 weeks; offer async questionnaires | I5: Engagement Lead | J5: Open
A6: R3 | B6: Risk | C6: Compressed 4-week assessment limits review time for D1–D3 | D6: 4 | E6: 3 | F6: =D6*E6 | G6: =IF(F6>=15,"High",IF(F6>=8,"Medium","Low")) | H6: Daily working sessions; pre-schedule readout for Oct 9; drafts shared incrementally | I6: Engagement Lead | J6: Open
A7: R4 | B7: Risk | C7: Remediation changes cause outages or business disruption | D7: 5 | E7: 2 | F7: =D7*E7 | G7: =IF(F7>=15,"High",IF(F7>=8,"Medium","Low")) | H7: CAB approval, maintenance windows, tested rollback, staged rollout | I7: NGFW Architect | J7: Open
A8: R6 | B8: Risk | C8: Limited change windows / holiday change freeze (late Nov, Dec) | D8: 4 | E8: 4 | F8: =D8*E8 | G8: =IF(F8>=15,"High",IF(F8>=8,"Medium","Low")) | H8: Front-load high-impact changes Oct–mid Nov; confirm freeze dates | I8: Client | J8: Open
A9: R5 | B9: Risk | C9: Incomplete CMDB / undocumented firewalls (shadow estate) | D9: 3 | E9: 3 | F9: =D9*E9 | G9: =IF(F9>=15,"High",IF(F9>=8,"Medium","Low")) | H9: Validate inventory against network scans & routing tables | I9: NGFW Architect | J9: Open
A10: I1 | B10: Issue | C10: Config export for cloud firewalls pending security approval | D10: 3 | E10: 5 | F10: =D10*E10 | G10: =IF(F10>=15,"High",IF(F10>=8,"Medium","Low")) | H10: Sponsor escalation requested | I10: Client | J10: Open

Sheet Inputs
A1: NGFW Maturity Engagement – Project Inputs
A3: Client | B3: Customer
A4: Engagement | B4: Next-Generation Firewall (NGFW) Maturity Assessment
A5: Project Start | B5: 46279
A6: Project End | B6: 46387
A7: Status Date (As-Of) | B7: =TODAY()
A8: Engagement Lead | B8: Engagement Lead
A9: Client Sponsor | B9: CISO
A12: Legend
A13: Yellow fill / blue text | B13: Editable input (dates, owners, % complete, status notes)
A14: Black text | B14: Formula – do not overwrite
A15: Holidays (excluded from working days)
A16: 46307 | B16: Columbus / Indigenous Peoples' Day
A17: 46337 | B17: Veterans Day
A18: 46352 | B18: Thanksgiving
A19: 46353 | B19: Day after Thanksgiving
A20: 46380 | B20: Christmas Eve
A21: 46381 | B21: Christmas Day
A23: Assumption: US holiday calendar; adjust to client calendar as needed.
